<?xml version="1.0" ?>
<!-- =================================================================================== -->
<!-- |    This document was autogenerated by xacro from urdf/edumip_my_robot.xacro     | -->
<!-- |    EDITING THIS FILE BY HAND IS NOT RECOMMENDED                                 | -->
<!-- =================================================================================== -->
<robot name="edumip141" xmlns:xacro="http://ros.org/wiki/xacro">
  <material name="blue">
    <color rgba="0 0 0.8 1"/>
  </material>
  <material name="green">
    <color rgba="0 0.8 0 1"/>
  </material>
  <material name="red">
    <color rgba="0.8 0 0 1"/>
  </material>
  <link name="edumip_body">
    <visual>
      <geometry>
        <box size="0.035 0.05 0.1"/>
      </geometry>
      <material name="blue"/>
    </visual>
    <collision>
      <geometry>
        <box size="0.035 0.05 0.1"/>
      </geometry>
    </collision>
    <inertial>
      <mass value="1"/>
      <inertia ixx="0.1" ixy="0.0" ixz="0.0" iyy="0.1" iyz="0.0" izz="0.1"/>
    </inertial>
  </link>
  <link name="wheelL">
    <visual>
      <origin rpy="0.035 0 0" xyz="0 0 0"/>
      <geometry>
        <cylinder length="0.01" radius="0.034"/>
      </geometry>
      <material name="green"/>
    </visual>
    <collision>
      <origin rpy="0.035 0 0" xyz="0 0 0"/>
      <geometry>
        <cylinder length="0.01" radius="0.034"/>
      </geometry>
    </collision>
    <inertial>
      <mass value="0.4"/>
      <inertia ixx="0.1" ixy="0.0" ixz="0.0" iyy="0.1" iyz="0.0" izz="0.1"/>
    </inertial>
  </link>
  <joint name="jointL" type="continuous">
    <axis rpy="0 0 0" xyz="0 1 0"/>
    <parent link="edumip_body"/>
    <child link="wheelL"/>
    <origin rpy="0 0 0" xyz="-0.035 0 -0.055"/>
  </joint>
  <link name="wheelR">
    <visual>
      <origin rpy="0.035 0 0" xyz="0 0 0"/>
      <geometry>
        <cylinder length="0.01" radius="0.034"/>
      </geometry>
      <material name="red"/>
    </visual>
    <collision>
      <origin rpy="0.035 0 0" xyz="0 0 0"/>
      <geometry>
        <cylinder length="0.01" radius="0.034"/>
      </geometry>
    </collision>
    <inertial>
      <mass value="0.4"/>
      <inertia ixx="0.1" ixy="0.0" ixz="0.0" iyy="0.1" iyz="0.0" izz="0.1"/>
    </inertial>
  </link>
  <joint name="jointR" type="continuous">
    <axis rpy="0 0 0" xyz="0 1 0"/>
    <parent link="edumip_body"/>
    <child link="wheelR"/>
    <origin rpy="0 0 0" xyz="0.035 0 -0.055"/>
  </joint>
</robot>

